Workbook

Sheet BEDFILE
A1: GENE | B1: SNP | C1: PESO | D1: T2D | E1: CARDIO | F1: VITA | G1: SPORT | H1: AGING | I1: MAMMA | J1: PLUS | L1: PLUS | M1: PESO | N1: T2D | O1: CARDIO | P1: VITA | Q1: SPORT | R1: AGING | S1: MAMMA
A2: MTHFR | B2: rs1801131 | C2: =VLOOKUP(B2,'RISCHIO PESO 3.0'!B:B,1,FALSE()) -> #N/A | D2: =VLOOKUP(B2,'RISCHIO T2D 3.0'!B:B,1,FALSE()) -> #N/A | E2: =VLOOKUP(B2,'RISCHIO CARDIO 3.0'!B:B,1,FALSE()) -> #N/A | F2: =VLOOKUP(B2,'RISCHIO VITA 3.0'!C:C,1,FALSE()) -> #N/A | G2: =VLOOKUP(B2,'RISCHIO SPORT'!B:B,1,FALSE()) -> #N/A | H2: =VLOOKUP(B2,'RISCHIO AGING '!B:B,1,FALSE()) -> #N/A | I2: =VLOOKUP(B2,'RISCHIO MAMMA'!B:B,1,FALSE()) -> #N/A | J2: =VLOOKUP(B2,'RIS PLUS3.0'!B:B,1,FALSE()) -> #N/A | O2: rs1801131 | P2: rs1801131
A3: MTHFR | B3: rs1801133 | C3: =VLOOKUP(B3,'RISCHIO PESO 3.0'!B:B,1,FALSE()) -> #N/A | D3: =VLOOKUP(B3,'RISCHIO T2D 3.0'!B:B,1,FALSE()) -> #N/A | E3: =VLOOKUP(B3,'RISCHIO CARDIO 3.0'!B:B,1,FALSE()) -> #N/A | F3: =VLOOKUP(B3,'RISCHIO VITA 3.0'!C:C,1,FALSE()) -> #N/A | G3: =VLOOKUP(B3,'RISCHIO SPORT'!B:B,1,FALSE()) -> #N/A | H3: =VLOOKUP(B3,'RISCHIO AGING '!B:B,1,FALSE()) -> #N/A | I3: =VLOOKUP(B3,'RISCHIO MAMMA'!B:B,1,FALSE()) -> #N/A | J3: =VLOOKUP(B3,'RIS PLUS3.0'!B:B,1,FALSE()) -> #N/A | O3: rs1801133 | P3: rs1801133
A4: CLCNKA | B4: rs848307 | C4: =VLOOKUP(B4,'RISCHIO PESO 3.0'!B:B,1,FALSE()) -> #N/A | D4: =VLOOKUP(B4,'RISCHIO T2D 3.0'!B:B,1,FALSE()) -> #N/A | E4: =VLOOKUP(B4,'RISCHIO CARDIO 3.0'!B:B,1,FALSE()) -> #N/A | F4: =VLOOKUP(B4,'RISCHIO VITA 3.0'!C:C,1,FALSE()) -> #N/A | G4: =VLOOKUP(B4,'RISCHIO SPORT'!B:B,1,FALSE()) -> #N/A | H4: =VLOOKUP(B4,'RISCHIO AGING '!B:B,1,FALSE()) -> #N/A | I4: =VLOOKUP(B4,'RISCHIO MAMMA'!B:B,1,FALSE()) -> #N/A | J4: =VLOOKUP(B4,'RIS PLUS3.0'!B:B,1,FALSE()) -> #N/A | S4: rs848307
A5: CLCNKA | B5: rs1739843 | C5: =VLOOKUP(B5,'RISCHIO PESO 3.0'!B:B,1,FALSE()) -> #N/A | D5: =VLOOKUP(B5,'RISCHIO T2D 3.0'!B:B,1,FALSE()) -> #N/A | E5: =VLOOKUP(B5,'RISCHIO CARDIO 3.0'!B:B,1,FALSE()) -> #N/A | F5: =VLOOKUP(B5,'RISCHIO VITA 3.0'!C:C,1,FALSE()) -> #N/A | G5: =VLOOKUP(B5,'RISCHIO SPORT'!B:B,1,FALSE()) -> #N/A | H5: =VLOOKUP(B5,'RISCHIO AGING '!B:B,1,FALSE()) -> #N/A | I5: =VLOOKUP(B5,'RISCHIO MAMMA'!B:B,1,FALSE()) -> #N/A | J5: =VLOOKUP(B5,'RIS PLUS3.0'!B:B,1,FALSE()) -> #N/A | S5: rs1739843
A6: CLCNKA | B6: rs1010069 | C6: =VLOOKUP(B6,'RISCHIO PESO 3.0'!B:B,1,FALSE()) -> #N/A | D6: =VLOOKUP(B6,'RISCHIO T2D 3.0'!B:B,1,FALSE()) -> #N/A | E6: =VLOOKUP(B6,'RISCHIO CARDIO 3.0'!B:B,1,FALSE()) -> #N/A | F6: =VLOOKUP(B6,'RISCHIO VITA 3.0'!C:C,1,FALSE()) -> #N/A | G6: =VLOOKUP(B6,'RISCHIO SPORT'!B:B,1,FALSE()) -> #N/A | H6: =VLOOKUP(B6,'RISCHIO AGING '!B:B,1,FALSE()) -> #N/A | I6: =VLOOKUP(B6,'RISCHIO MAMMA'!B:B,1,FALSE()) -> #N/A | J6: =VLOOKUP(B6,'RIS PLUS3.0'!B:B,1,FALSE()) -> #N/A | S6: rs1010069
A7: ALPL | B7: rs4654748 | C7: =VLOOKUP(B7,'RISCHIO PESO 3.0'!B:B,1,FALSE()) -> #N/A | D7: =VLOOKUP(B7,'RISCHIO T2D 3.0'!B:B,1,FALSE()) -> #N/A | E7: =VLOOKUP(B7,'RISCHIO CARDIO 3.0'!B:B,1,FALSE()) -> #N/A | F7: =VLOOKUP(B7,'RISCHIO VITA 3.0'!C:C,1,FALSE()) -> #N/A | G7: =VLOOKUP(B7,'RISCHIO SPORT'!B:B,1,FALSE()) -> #N/A | H7: =VLOOKUP(B7,'RISCHIO AGING '!B:B,1,FALSE()) -> #N/A | I7: =VLOOKUP(B7,'RISCHIO MAMMA'!B:B,1,FALSE()) -> rs4654748 | J7: =VLOOKUP(B7,'RIS PLUS3.0'!B:B,1,FALSE()) -> #N/A | S7: rs4654748
A8: ALPL | B8: rs1256335 | C8: =VLOOKUP(B8,'RISCHIO PESO 3.0'!B:B,1,FALSE()) -> #N/A | D8: =VLOOKUP(B8,'RISCHIO T2D 3.0'!B:B,1,FALSE()) -> #N/A | E8: =VLOOKUP(B8,'RISCHIO CARDIO 3.0'!B:B,1,FALSE()) -> #N/A | F8: =VLOOKUP(B8,'RISCHIO VITA 3.0'!C:C,1,FALSE()) -> #N/A | G8: =VLOOKUP(B8,'RISCHIO SPORT'!B:B,1,FALSE()) -> #N/A | H8: =VLOOKUP(B8,'RISCHIO AGING '!B:B,1,FALSE()) -> #N/A | I8: =VLOOKUP(B8,'RISCHIO MAMMA'!B:B,1,FALSE()) -> rs1256335 | J8: =VLOOKUP(B8,'RIS PLUS3.0'!B:B,1,FALSE()) -> #N/A | S8: rs1256335
A9: SLC30A2 | B9: rs35623192 | C9: =VLOOKUP(B9,'RISCHIO PESO 3.0'!B:B,1,FALSE()) -> #N/A | D9: =VLOOKUP(B9,'RISCHIO T2D 3.0'!B:B,1,FALSE()) -> #N/A | E9: =VLOOKUP(B9,'RISCHIO CARDIO 3.0'!B:B,1,FALSE()) -> #N/A | F9: =VLOOKUP(B9,'RISCHIO VITA 3.0'!C:C,1,FALSE()) -> #N/A | G9: =VLOOKUP(B9,'RISCHIO SPORT'!B:B,1,FALSE()) -> #N/A | H9: =VLOOKUP(B9,'RISCHIO AGING '!B:B,1,FALSE()) -> #N/A | I9: =VLOOKUP(B9,'RISCHIO MAMMA'!B:B,1,FALSE()) -> rs35623192 | J9: =VLOOKUP(B9,'RIS PLUS3.0'!B:B,1,FALSE()) -> #N/A | S9: rs35623192
A10: SLC30A2 | B10: rs35235055 | C10: =VLOOKUP(B10,'RISCHIO PESO 3.0'!B:B,1,FALSE()) -> #N/A | D10: =VLOOKUP(B10,'RISCHIO T2D 3.0'!B:B,1,FALSE()) -> #N/A | E10: =VLOOKUP(B10,'RISCHIO CARDIO 3.0'!B:B,1,FALSE()) -> #N/A | F10: =VLOOKUP(B10,'RISCHIO VITA 3.0'!C:C,1,FALSE()) -> #N/A | G10: =VLOOKUP(B10,'RISCHIO SPORT'!B:B,1,FALSE()) -> #N/A | H10: =VLOOKUP(B10,'RISCHIO AGING '!B:B,1,FALSE()) -> #N/A | I10: =VLOOKUP(B10,'RISCHIO MAMMA'!B:B,1,FALSE()) -> rs35235055 | J10: =VLOOKUP(B10,'RIS PLUS3.0'!B:B,1,FALSE()) -> #N/A | S10: rs35235055
A11: PCSK9 | B11: rs11591147 | C11: =VLOOKUP(B11,'RISCHIO PESO 3.0'!B:B,1,FALSE()) -> #N/A | D11: =VLOOKUP(B11,'RISCHIO T2D 3.0'!B:B,1,FALSE()) -> #N/A | E11: =VLOOKUP(B11,'RISCHIO CARDIO 3.0'!B:B,1,FALSE()) -> #N/A | F11: =VLOOKUP(B11,'RISCHIO VITA 3.0'!C:C,1,FALSE()) -> #N/A | G11: =VLOOKUP(B11,'RISCHIO SPORT'!B:B,1,FALSE()) -> #N/A | H11: =VLOOKUP(B11,'RISCHIO AGING '!B:B,1,FALSE()) -> #N/A | I11: =VLOOKUP(B11,'RISCHIO MAMMA'!B:B,1,FALSE()) -> #N/A | J11: =VLOOKUP(B11,'RIS PLUS3.0'!B:B,1,FALSE()) -> #N/A
A12: LEPR | B12: rs11208659 | C12: =VLOOKUP(B12,'RISCHIO PESO 3.0'!B:B,1,FALSE()) -> rs11208659 | D12: =VLOOKUP(B12,'RISCHIO T2D 3.0'!B:B,1,FALSE()) -> #N/A | E12: =VLOOKUP(B12,'RISCHIO CARDIO 3.0'!B:B,1,FALSE()) -> #N/A | F12: =VLOOKUP(B12,'RISCHIO VITA 3.0'!C:C,1,FALSE()) -> #N/A | G12: =VLOOKUP(B12,'RISCHIO SPORT'!B:B,1,FALSE()) -> #N/A | H12: =VLOOKUP(B12,'RISCHIO AGING '!B:B,1,FALSE()) -> #N/A | I12: =VLOOKUP(B12,'RISCHIO MAMMA'!B:B,1,FALSE()) -> #N/A | J12: =VLOOKUP(B12,'RIS PLUS3.0'!B:B,1,FALSE()) -> #N/A | M12: rs11208659
A13: MCT1 | B13: rs1049434 | C13: =VLOOKUP(B13,'RISCHIO PESO 3.0'!B:B,1,FALSE()) -> #N/A | D13: =VLOOKUP(B13,'RISCHIO T2D 3.0'!B:B,1,FALSE()) -> #N/A | E13: =VLOOKUP(B13,'RISCHIO CARDIO 3.0'!B:B,1,FALSE()) -> #N/A | F13: =VLOOKUP(B13,'RISCHIO VITA 3.0'!C:C,1,FALSE()) -> #N/A | G13: =VLOOKUP(B13,'RISCHIO SPORT'!B:B,1,FALSE()) -> rs1049434 | H13: =VLOOKUP(B13,'RISCHIO AGING '!B:B,1,FALSE()) -> #N/A | I13: =VLOOKUP(B13,'RISCHIO MAMMA'!B:B,1,FALSE()) -> #N/A | J13: =VLOOKUP(B13,'RIS PLUS3.0'!B:B,1,FALSE()) -> #N/A | Q13: rs1049434
A14: TUFT1 | B14: rs2337360 | C14: =VLOOKUP(B14,'RISCHIO PESO 3.0'!B:B,1,FALSE()) -> #N/A | D14: =VLOOKUP(B14,'RISCHIO T2D 3.0'!B:B,1,FALSE()) -> #N/A | E14: =VLOOKUP(B14,'RISCHIO CARDIO 3.0'!B:B,1,FALSE()) -> #N/A | F14: =VLOOKUP(B14,'RISCHIO VITA 3.0'!C:C,1,FALSE()) -> #N/A | G14: =VLOOKUP(B14,'RISCHIO SPORT'!B:B,1,FALSE()) -> #N/A | H14: =VLOOKUP(B14,'RISCHIO AGING '!B:B,1,FALSE()) -> #N/A | I14: =VLOOKUP(B14,'RISCHIO MAMMA'!B:B,1,FALSE()) -> #N/A | J14: =VLOOKUP(B14,'RIS PLUS3.0'!B:B,1,FALSE()) -> #N/A
A15: CRP | B15: rs1205 | C15: =VLOOKUP(B15,'RISCHIO PESO 3.0'!B:B,1,FALSE()) -> #N/A | D15: =VLOOKUP(B15,'RISCHIO T2D 3.0'!B:B,1,FALSE()) -> #N/A | E15: =VLOOKUP(B15,'RISCHIO CARDIO 3.0'!B:B,1,FALSE()) -> #N/A | F15: =VLOOKUP(B15,'RISCHIO VITA 3.0'!C:C,1,FALSE()) -> #N/A | G15: =VLOOKUP(B15,'RISCHIO SPORT'!B:B,1,FALSE()) -> #N/A | H15: =VLOOKUP(B15,'RISCHIO AGING '!B:B,1,FALSE()) -> rs1205 | I15: =VLOOKUP(B15,'RISCHIO MAMMA'!B:B,1,FALSE()) -> #N/A | J15: =VLOOKUP(B15,'RIS PLUS3.0'!B:B,1,FALSE()) -> #N/A | R15: rs1205
A16: APOA2 | B16: rs5082 | C16: =VLOOKUP(B16,'RISCHIO PESO 3.0'!B:B,1,FALSE()) -> rs5082 | D16: =VLOOKUP(B16,'RISCHIO T2D 3.0'!B:B,1,FALSE()) -> #N/A | E16: =VLOOKUP(B16,'RISCHIO CARDIO 3.0'!B:B,1,FALSE()) -> #N/A | F16: =VLOOKUP(B16,'RISCHIO VITA 3.0'!C:C,1,FALSE()) -> #N/A | G16: =VLOOKUP(B16,'RISCHIO SPORT'!B:B,1,FALSE()) -> #N/A | H16: =VLOOKUP(B16,'RISCHIO AGING '!B:B,1,FALSE()) -> #N/A | I16: =VLOOKUP(B16,'RISCHIO MAMMA'!B:B,1,FALSE()) -> #N/A | J16: =VLOOKUP(B16,'RIS PLUS3.0'!B:B,1,FALSE()) -> #N/A | M16: rs5082
A17: AGT | B17: rs699 | C17: =VLOOKUP(B17,'RISCHIO PESO 3.0'!B:B,1,FALSE()) -> #N/A | D17: =VLOOKUP(B17,'RISCHIO T2D 3.0'!B:B,1,FALSE()) -> #N/A | E17: =VLOOKUP(B17,'RISCHIO CARDIO 3.0'!B:B,1,FALSE()) -> #N/A | F17: =VLOOKUP(B17,'RISCHIO VITA 3.0'!C:C,1,FALSE()) -> #N/A | G17: =VLOOKUP(B17,'RISCHIO SPORT'!B:B,1,FALSE()) -> #N/A | H17: =VLOOKUP(B17,'RISCHIO AGING '!B:B,1,FALSE()) -> #N/A | I17: =VLOOKUP(B17,'RISCHIO MAMMA'!B:B,1,FALSE()) -> #N/A | J17: =VLOOKUP(B17,'RIS PLUS3.0'!B:B,1,FALSE()) -> #N/A | S17: rs699
A18: AGT | B18: rs5051 | C18: =VLOOKUP(B18,'RISCHIO PESO 3.0'!B:B,1,FALSE()) -> #N/A | D18: =VLOOKUP(B18,'RISCHIO T2D 3.0'!B:B,1,FALSE()) -> #N/A | E18: =VLOOKUP(B18,'RISCHIO CARDIO 3.0'!B:B,1,FALSE()) -> #N/A | F18: =VLOOKUP(B18,'RISCHIO VITA 3.0'!C:C,1,FALSE()) -> #N/A | G18: =VLOOKUP(B18,'RISCHIO SPORT'!B:B,1,FALSE()) -> #N/A | H18: =VLOOKUP(B18,'RISCHIO AGING '!B:B,1,FALSE()) -> #N/A | I18: =VLOOKUP(B18,'RISCHIO MAMMA'!B:B,1,FALSE()) -> rs5051 | J18: =VLOOKUP(B18,'RIS PLUS3.0'!B:B,1,FALSE()) -> #N/A | S18: rs5051
A19: AGT | B19: rs5050 | C19: =VLOOKUP(B19,'RISCHIO PESO 3.0'!B:B,1,FALSE()) -> #N/A | D19: =VLOOKUP(B19,'RISCHIO T2D 3.0'!B:B,1,FALSE()) -> #N/A | E19: =VLOOKUP(B19,'RISCHIO CARDIO 3.0'!B:B,1,FALSE()) -> #N/A | F19: =VLOOKUP(B19,'RISCHIO VITA 3.0'!C:C,1,FALSE()) -> #N/A | G19: =VLOOKUP(B19,'RISCHIO SPORT'!B:B,1,FALSE()) -> #N/A | H19: =VLOOKUP(B19,'RISCHIO AGING '!B:B,1,FALSE()) -> #N/A | I19: =VLOOKUP(B19,'RISCHIO MAMMA'!B:B,1,FALSE()) -> rs5050 | J19: =VLOOKUP(B19,'RIS PLUS3.0'!B:B,1,FALSE()) -> #N/A | S19: rs5050
A20: AGT | B20: rs11568020 | C20: =VLOOKUP(B20,'RISCHIO PESO 3.0'!B:B,1,FALSE()) -> #N/A | D20: =VLOOKUP(B20,'RISCHIO T2D 3.0'!B:B,1,FALSE()) -> #N/A | E20: =VLOOKUP(B20,'RISCHIO CARDIO 3.0'!B:B,1,FALSE()) -> #N/A | F20: =VLOOKUP(B20,'RISCHIO VITA 3.0'!C:C,1,FALSE()) -> #N/A | G20: =VLOOKUP(B20,'RISCHIO SPORT'!B:B,1,FALSE()) -> #N/A | H20: =VLOOKUP(B20,'RISCHIO AGING '!B:B,1,FALSE()) -> #N/A | I20: =VLOOKUP(B20,'RISCHIO MAMMA'!B:B,1,FALSE()) -> rs11568020 | J20: =VLOOKUP(B20,'RIS PLUS3.0'!B:B,1,FALSE()) -> #N/A | S20: rs11568020
A21: TMEM18 | B21: rs6548238 | C21: =VLOOKUP(B21,'RISCHIO PESO 3.0'!B:B,1,FALSE()) -> rs6548238 | D21: =VLOOKUP(B21,'RISCHIO T2D 3.0'!B:B,1,FALSE()) -> #N/A | E21: =VLOOKUP(B21,'RISCHIO CARDIO 3.0'!B:B,1,FALSE()) -> #N/A | F21: =VLOOKUP(B21,'RISCHIO VITA 3.0'!C:C,1,FALSE()) -> #N/A | G21: =VLOOKUP(B21,'RISCHIO SPORT'!B:B,1,FALSE()) -> #N/A | H21: =VLOOKUP(B21,'RISCHIO AGING '!B:B,1,FALSE()) -> #N/A | I21: =VLOOKUP(B21,'RISCHIO MAMMA'!B:B,1,FALSE()) -> #N/A | J21: =VLOOKUP(B21,'RIS PLUS3.0'!B:B,1,FALSE()) -> #N/A | M21: rs6548238
A22: GCKR | B22: rs780094 | C22: =VLOOKUP(B22,'RISCHIO PESO 3.0'!B:B,1,FALSE()) -> #N/A | D22: =VLOOKUP(B22,'RISCHIO T2D 3.0'!B:B,1,FALSE()) -> rs780094 | E22: =VLOOKUP(B22,'RISCHIO CARDIO 3.0'!B:B,1,FALSE()) -> #N/A | F22: =VLOOKUP(B22,'RISCHIO VITA 3.0'!C:C,1,FALSE()) -> #N/A | G22: =VLOOKUP(B22,'RISCHIO SPORT'!B:B,1,FALSE()) -> #N/A | H22: =VLOOKUP(B22,'RISCHIO AGING '!B:B,1,FALSE()) -> #N/A | I22: =VLOOKUP(B22,'RISCHIO MAMMA'!B:B,1,FALSE()) -> #N/A | J22: =VLOOKUP(B22,'RIS PLUS3.0'!B:B,1,FALSE()) -> #N/A | N22: rs780094 | O22: rs780094
A23: IL1B | B23: rs1143634 | C23: =VLOOKUP(B23,'RISCHIO PESO 3.0'!B:B,1,FALSE()) -> #N/A | D23: =VLOOKUP(B23,'RISCHIO T2D 3.0'!B:B,1,FALSE()) -> #N/A | E23: =VLOOKUP(B23,'RISCHIO CARDIO 3.0'!B:B,1,FALSE()) -> #N/A | F23: =VLOOKUP(B23,'RISCHIO VITA 3.0'!C:C,1,FALSE()) -> #N/A | G23: =VLOOKUP(B23,'RISCHIO SPORT'!B:B,1,FALSE()) -> #N/A | H23: =VLOOKUP(B23,'RISCHIO AGING '!B:B,1,FALSE()) -> rs1143634 | I23: =VLOOKUP(B23,'RISCHIO MAMMA'!B:B,1,FALSE()) -> #N/A | J23: =VLOOKUP(B23,'RIS PLUS3.0'!B:B,1,FALSE()) -> #N/A | R23: rs1143634
A24: IL1B | B24: rs1143633 | C24: =VLOOKUP(B24,'RISCHIO PESO 3.0'!B:B,1,FALSE()) -> #N/A | D24: =VLOOKUP(B24,'RISCHIO T2D 3.0'!B:B,1,FALSE()) -> #N/A | E24: =VLOOKUP(B24,'RISCHIO CARDIO 3.0'!B:B,1,FALSE()) -> #N/A | F24: =VLOOKUP(B24,'RISCHIO VITA 3.0'!C:C,1,FALSE()) -> #N/A | G24: =VLOOKUP(B24,'RISCHIO SPORT'!B:B,1,FALSE()) -> #N/A | H24: =VLOOKUP(B24,'RISCHIO AGING '!B:B,1,FALSE()) -> rs1143633 | I24: =VLOOKUP(B24,'RISCHIO MAMMA'!B:B,1,FALSE()) -> #N/A | J24: =VLOOKUP(B24,'RIS PLUS3.0'!B:B,1,FALSE()) -> #N/A | R24: rs1143633
A25: IL1B | B25: rs16944 | C25: =VLOOKUP(B25,'RISCHIO PESO 3.0'!B:B,1,FALSE()) -> #N/A | D25: =VLOOKUP(B25,'RISCHIO T2D 3.0'!B:B,1,FALSE()) -> #N/A | E25: =VLOOKUP(B25,'RISCHIO CARDIO 3.0'!B:B,1,FALSE()) -> #N/A | F25: =VLOOKUP(B25,'RISCHIO VITA 3.0'!C:C,1,FALSE()) -> #N/A | G25: =VLOOKUP(B25,'RISCHIO SPORT'!B:B,1,FALSE()) -> #N/A | H25: =VLOOKUP(B25,'RISCHIO AGING '!B:B,1,FALSE()) -> rs16944 | I25: =VLOOKUP(B25,'RISCHIO MAMMA'!B:B,1,FALSE()) -> #N/A | J25: =VLOOKUP(B25,'RIS PLUS3.0'!B:B,1,FALSE()) -> #N/A | R25: rs16944
A26: LCT | B26: rs4988235 | C26: =VLOOKUP(B26,'RISCHIO PESO 3.0'!B:B,1,FALSE()) -> #N/A | D26: =VLOOKUP(B26,'RISCHIO T2D 3.0'!B:B,1,FALSE()) -> #N/A | E26: =VLOOKUP(B26,'RISCHIO CARDIO 3.0'!B:B,1,FALSE()) -> #N/A | F26: =VLOOKUP(B26,'RISCHIO VITA 3.0'!C:C,1,FALSE()) -> #N/A | G26: =VLOOKUP(B26,'RISCHIO SPORT'!B:B,1,FALSE()) -> #N/A | H26: =VLOOKUP(B26,'RISCHIO AGING '!B:B,1,FALSE()) -> #N/A | I26: =VLOOKUP(B26,'RISCHIO MAMMA'!B:B,1,FALSE()) -> #N/A | J26: =VLOOKUP(B26,'RIS PLUS3.0'!B:B,1,FALSE()) -> #N/A | L26: rs4988235
A27: LCT | B27: rs182549 | C27: =VLOOKUP(B27,'RISCHIO PESO 3.0'!B:B,1,FALSE()) -> #N/A | D27: =VLOOKUP(B27,'RISCHIO T2D 3.0'!B:B,1,FALSE()) -> #N/A | E27: =VLOOKUP(B27,'RISCHIO CARDIO 3.0'!B:B,1,FALSE()) -> #N/A | F27: =VLOOKUP(B27,'RISCHIO VITA 3.0'!C:C,1,FALSE()) -> #N/A | G27: =VLOOKUP(B27,'RISCHIO SPORT'!B:B,1,FALSE()) -> #N/A | H27: =VLOOKUP(B27,'RISCHIO AGING '!B:B,1,FALSE()) -> #N/A | I27: =VLOOKUP(B27,'RISCHIO MAMMA'!B:B,1,FALSE()) -> #N/A | J27: =VLOOKUP(B27,'RIS PLUS3.0'!B:B,1,FALSE()) -> #N/A
A28: PPARG | B28: rs1801282 | C28: =VLOOKUP(B28,'RISCHIO PESO 3.0'!B:B,1,FALSE()) -> rs1801282 | D28: =VLOOKUP(B28,'RISCHIO T2D 3.0'!B:B,1,FALSE()) -> rs1801282 | E28: =VLOOKUP(B28,'RISCHIO CARDIO 3.0'!B:B,1,FALSE()) -> #N/A | F28: =VLOOKUP(B28,'RISCHIO VITA 3.0'!C:C,1,FALSE()) -> #N/A | G28: =VLOOKUP(B28,'RISCHIO SPORT'!B:B,1,FALSE()) -> #N/A | H28: =VLOOKUP(B28,'RISCHIO AGING '!B:B,1,FALSE()) -> #N/A | I28: =VLOOKUP(B28,'RISCHIO MAMMA'!B:B,1,FALSE()) -> #N/A | J28: =VLOOKUP(B28,'RIS PLUS3.0'!B:B,1,FALSE()) -> #N/A | M28: rs1801282 | N28: rs1801282 | O28: rs1801282
A29: GPX1 | B29: rs1050450 | C29: =VLOOKUP(B29,'RISCHIO PESO 3.0'!B:B,1,FALSE()) -> #N/A | D29: =VLOOKUP(B29,'RISCHIO T2D 3.0'!B:B,1,FALSE()) -> #N/A | E29: =VLOOKUP(B29,'RISCHIO CARDIO 3.0'!B:B,1,FALSE()) -> #N/A | F29: =VLOOKUP(B29,'RISCHIO VITA 3.0'!C:C,1,FALSE()) -> #N/A | G29: =VLOOKUP(B29,'RISCHIO SPORT'!B:B,1,FALSE()) -> #N/A | H29: =VLOOKUP(B29,'RISCHIO AGING '!B:B,1,FALSE()) -> rs1050450 | I29: =VLOOKUP(B29,'RISCHIO MAMMA'!B:B,1,FALSE()) -> #N/A | J29: =VLOOKUP(B29,'RIS PLUS3.0'!B:B,1,FALSE()) -> #N/A | R29: rs1050450
A30: SLC2A2 | B30: rs5400 | C30: =VLOOKUP(B30,'RISCHIO PESO 3.0'!B:B,1,FALSE()) -> #N/A | D30: =VLOOKUP(B30,'RISCHIO T2D 3.0'!B:B,1,FALSE()) -> rs5400 | E30: =VLOOKUP(B30,'RISCHIO CARDIO 3.0'!B:B,1,FALSE()) -> #N/A | F30: =VLOOKUP(B30,'RISCHIO VITA 3.0'!C:C,1,FALSE()) -> #N/A | G30: =VLOOKUP(B30,'RISCHIO SPORT'!B:B,1,FALSE()) -> #N/A | H30: =VLOOKUP(B30,'RISCHIO AGING '!B:B,1,FALSE()) -> #N/A | I30: =VLOOKUP(B30,'RISCHIO MAMMA'!B:B,1,FALSE()) -> #N/A | J30: =VLOOKUP(B30,'RIS PLUS3.0'!B:B,1,FALSE()) -> #N/A
A31: ADIPOQ | B31: rs17300539 | C31: =VLOOKUP(B31,'RISCHIO PESO 3.0'!B:B,1,FALSE()) -> rs17300539 | D31: =VLOOKUP(B31,'RISCHIO T2D 3.0'!B:B,1,FALSE()) -> rs17300539 | E31: =VLOOKUP(B31,'RISCHIO CARDIO 3.0'!B:B,1,FALSE()) -> #N/A | F31: =VLOOKUP(B31,'RISCHIO VITA 3.0'!C:C,1,FALSE()) -> #N/A | G31: =VLOOKUP(B31,'RISCHIO SPORT'!B:B,1,FALSE()) -> #N/A | H31: =VLOOKUP(B31,'RISCHIO AGING '!B:B,1,FALSE()) -> #N/A | I31: =VLOOKUP(B31,'RISCHIO MAMMA'!B:B,1,FALSE()) -> #N/A | J31: =VLOOKUP(B31,'RIS PLUS3.0'!B:B,1,FALSE()) -> #N/A | M31: rs17300539 | N31: rs17300539 | O31: rs17300539
A32: ADD1 | B32: rs4961 | C32: =VLOOKUP(B32,'RISCHIO PESO 3.0'!B:B,1,FALSE()) -> #N/A | D32: =VLOOKUP(B32,'RISCHIO T2D 3.0'!B:B,1,FALSE()) -> #N/A | E32: =VLOOKUP(B32,'RISCHIO CARDIO 3.0'!B:B,1,FALSE()) -> #N/A | F32: =VLOOKUP(B32,'RISCHIO VITA 3.0'!C:C,1,FALSE()) -> #N/A | G32: =VLOOKUP(B32,'RISCHIO SPORT'!B:B,1,FALSE()) -> #N/A | H32: =VLOOKUP(B32,'RISCHIO AGING '!B:B,1,FALSE()) -> #N/A | I32: =VLOOKUP(B32,'RISCHIO MAMMA'!B:B,1,FALSE()) -> #N/A | J32: =VLOOKUP(B32,'RIS PLUS3.0'!B:B,1,FALSE()) -> #N/A | S32: rs4961
A33: SOD3 | B33: rs13306703 | C33: =VLOOKUP(B33,'RISCHIO PESO 3.0'!B:B,1,FALSE()) -> #N/A | D33: =VLOOKUP(B33,'RISCHIO T2D 3.0'!B:B,1,FALSE()) -> #N/A | E33: =VLOOKUP(B33,'RISCHIO CARDIO 3.0'!B:B,1,FALSE()) -> #N/A | F33: =VLOOKUP(B33,'RISCHIO VITA 3.0'!C:C,1,FALSE()) -> #N/A | G33: =VLOOKUP(B33,'RISCHIO SPORT'!B:B,1,FALSE()) -> #N/A | H33: =VLOOKUP(B33,'RISCHIO AGING '!B:B,1,FALSE()) -> rs13306703 | I33: =VLOOKUP(B33,'RISCHIO MAMMA'!B:B,1,FALSE()) -> #N/A | J33: =VLOOKUP(B33,'RIS PLUS3.0'!B:B,1,FALSE()) -> #N/A | R33: rs13306703
A34: SOD3 | B34: rs699473 | C34: =VLOOKUP(B34,'RISCHIO PESO 3.0'!B:B,1,FALSE()) -> #N/A | D34: =VLOOKUP(B34,'RISCHIO T2D 3.0'!B:B,1,FALSE()) -> #N/A | E34: =VLOOKUP(B34,'RISCHIO CARDIO 3.0'!B:B,1,FALSE()) -> #N/A | F34: =VLOOKUP(B34,'RISCHIO VITA 3.0'!C:C,1,FALSE()) -> #N/A | G34: =VLOOKUP(B34,'RISCHIO SPORT'!B:B,1,FALSE()) -> #N/A | H34: =VLOOKUP(B34,'RISCHIO AGING '!B:B,1,FALSE()) -> rs699473 | I34: =VLOOKUP(B34,'RISCHIO MAMMA'!B:B,1,FALSE()) -> #N/A | J34: =VLOOKUP(B34,'RIS PLUS3.0'!B:B,1,FALSE()) -> #N/A | R34: rs699473
A35: SOD3 | B35: rs2536512 | C35: =VLOOKUP(B35,'RISCHIO PESO 3.0'!B:B,1,FALSE()) -> #N/A | D35: =VLOOKUP(B35,'RISCHIO T2D 3.0'!B:B,1,FALSE()) -> #N/A | E35: =VLOOKUP(B35,'RISCHIO CARDIO 3.0'!B:B,1,FALSE()) -> #N/A | F35: =VLOOKUP(B35,'RISCHIO VITA 3.0'!C:C,1,FALSE()) -> #N/A | G35: =VLOOKUP(B35,'RISCHIO SPORT'!B:B,1,FALSE()) -> #N/A | H35: =VLOOKUP(B35,'RISCHIO AGING '!B:B,1,FALSE()) -> rs2536512 | I35: =VLOOKUP(B35,'RISCHIO MAMMA'!B:B,1,FALSE()) -> #N/A | J35: =VLOOKUP(B35,'RIS PLUS3.0'!B:B,1,FALSE()) -> #N/A | R35: rs2536512
A36: SOD3 | B36: rs1799895 | C36: =VLOOKUP(B36,'RISCHIO PESO 3.0'!B:B,1,FALSE()) -> #N/A | D36: =VLOOKUP(B36,'RISCHIO T2D 3.0'!B:B,1,FALSE()) -> #N/A | E36: =VLOOKUP(B36,'RISCHIO CARDIO 3.0'!B:B,1,FALSE()) -> #N/A | F36: =VLOOKUP(B36,'RISCHIO VITA 3.0'!C:C,1,FALSE()) -> #N/A | G36: =VLOOKUP(B36,'RISCHIO SPORT'!B:B,1,FALSE()) -> #N/A | H36: =VLOOKUP(B36,'RISCHIO AGING '!B:B,1,FALSE()) -> rs1799895 | I36: =VLOOKUP(B36,'RISCHIO MAMMA'!B:B,1,FALSE()) -> #N/A | J36: =VLOOKUP(B36,'RIS PLUS3.0'!B:B,1,FALSE()) -> #N/A | R36: rs1799895
A37: GNPDA2 | B37: rs10938397 | C37: =VLOOKUP(B37,'RISCHIO PESO 3.0'!B:B,1,FALSE()) -> rs10938397 | D37: =VLOOKUP(B37,'RISCHIO T2D 3.0'!B:B,1,FALSE()) -> #N/A | E37: =VLOOKUP(B37,'RISCHIO CARDIO 3.0'!B:B,1,FALSE()) -> #N/A | F37: =VLOOKUP(B37,'RISCHIO VITA 3.0'!C:C,1,FALSE()) -> #N/A | G37: =VLOOKUP(B37,'RISCHIO SPORT'!B:B,1,FALSE()) -> #N/A | H37: =VLOOKUP(B37,'RISCHIO AGING '!B:B,1,FALSE()) -> #N/A | I37: =VLOOKUP(B37,'RISCHIO MAMMA'!B:B,1,FALSE()) -> #N/A | J37: =VLOOKUP(B37,'RIS PLUS3.0'!B:B,1,FALSE()) -> #N/A | M37: rs10938397
A38: AMBN | B38: rs4694075 | C38: =VLOOKUP(B38,'RISCHIO PESO 3.0'!B:B,1,FALSE()) -> #N/A | D38: =VLOOKUP(B38,'RISCHIO T2D 3.0'!B:B,1,FALSE()) -> #N/A | E38: =VLOOKUP(B38,'RISCHIO CARDIO 3.0'!B:B,1,FALSE()) -> #N/A | F38: =VLOOKUP(B38,'RISCHIO VITA 3.0'!C:C,1,FALSE()) -> #N/A | G38: =VLOOKUP(B38,'RISCHIO SPORT'!B:B,1,FALSE()) -> #N/A | H38: =VLOOKUP(B38,'RISCHIO AGING '!B:B,1,FALSE()) -> #N/A | I38: =VLOOKUP(B38,'RISCHIO MAMMA'!B:B,1,FALSE()) -> #N/A | J38: =VLOOKUP(B38,'RIS PLUS3.0'!B:B,1,FALSE()) -> #N/A
A39: AMBN | B39: rs34538475 | C39: =VLOOKUP(B39,'RISCHIO PESO 3.0'!B:B,1,FALSE()) -> #N/A | D39: =VLOOKUP(B39,'RISCHIO T2D 3.0'!B:B,1,FALSE()) -> #N/A | E39: =VLOOKUP(B39,'RISCHIO CARDIO 3.0'!B:B,1,FALSE()) -> #N/A | F39: =VLOOKUP(B39,'RISCHIO VITA 3.0'!C:C,1,FALSE()) -> #N/A | G39: =VLOOKUP(B39,'RISCHIO SPORT'!B:B,1,FALSE()) -> #N/A | H39: =VLOOKUP(B39,'RISCHIO AGING '!B:B,1,FALSE()) -> #N/A | I39: =VLOOKUP(B39,'RISCHIO MAMMA'!B:B,1,FALSE()) -> #N/A | J39: =VLOOKUP(B39,'RIS PLUS3.0'!B:B,1,FALSE()) -> #N/A
A40: GC | B40: rs4588 | C40: =VLOOKUP(B40,'RISCHIO PESO 3.0'!B:B,1,FALSE()) -> #N/A | D40: =VLOOKUP(B40,'RISCHIO T2D 3.0'!B:B,1,FALSE()) -> #N/A | E40: =VLOOKUP(B40,'RISCHIO CARDIO 3.0'!B:B,1,FALSE()) -> #N/A | F40: =VLOOKUP(B40,'RISCHIO VITA 3.0'!C:C,1,FALSE()) -> #N/A | G40: =VLOOKUP(B40,'RISCHIO SPORT'!B:B,1,FALSE()) -> #N/A | H40: =VLOOKUP(B40,'RISCHIO AGING '!B:B,1,FALSE()) -> #N/A | I40: =VLOOKUP(B40,'RISCHIO MAMMA'!B:B,1,FALSE()) -> #N/A | J40: =VLOOKUP(B40,'RIS PLUS3.0'!B:B,1,FALSE()) -> #N/A
...

Sheet RISCHIO PESO 3.0
A1: GENE | B1: SNP | C1: GEN | D1: CHECK | E1: PESO | F1: NOTE
A2: ADIPOq | B2: rs17300539 | C2: CC | E2: 1 | F2: livelli di adiponectina ridotti
A3: ADIPOq | B3: rs17300539 | C3: CT | E3: 0
A4: ADIPOq | B4: rs17300539 | C4: TT | E4: -1 | F4: livelli di adiponectina aumentati
A5: APOA2 | B5: rs5082 | C5: GG | E5: 2
A6: APOA2 | B6: rs5082 | C6: GA | E6: 1
A7: APOA2 | B7: rs5082 | C7: AA | E7: 0
A8: BDNF | B8: rs6265 | C8: TT | E8: 0 | F8: s6265(A;A) women had a lower body mass
A9: BDNF | B9: rs6265 | C9: TC | E9: 0
A10: BDNF | B10: rs6265 | C10: CC | E10: 1
A11: FABP2 | B11: rs1799883 | C11: TT | E11: 1
A12: FABP2 | B12: rs1799883 | C12: TC | E12: 0
A13: FABP2 | B13: rs1799883 | C13: CC | E13: 0
A14: FTO | B14: rs9939609 | C14: AA | E14: 5
A15: FTO | B15: rs9939609 | C15: AT | E15: 3
A16: FTO | B16: rs9939609 | C16: TT | E16: 0
A17: FTO | B17: rs1421085 | C17: CC | E17: 5
A18: FTO | B18: rs1421085 | C18: CT | E18: 3
A19: FTO | B19: rs1421085 | C19: TT | E19: 0
A20: FTO | B20: rs1121980 | C20: GG | E20: 0 | F20: NEW
A21: FTO | B21: rs1121980 | C21: GA | E21: 3 | F21: NEW
A22: FTO | B22: rs1121980 | C22: AA | E22: 5 | F22: NEW
A23: FTO | B23: rs1558902 | C23: TT | E23: 0 | F23: NEW
A24: FTO | B24: rs1558902 | C24: AT | E24: 1 | F24: NEW
A25: FTO | B25: rs1558902 | C25: AA | E25: 2 | F25: NEW
A26: FTO | B26: rs8050136 | C26: AA | E26: 5 | F26: NEW
A27: FTO | B27: rs8050136 | C27: AC | E27: 3 | F27: NEW
A28: FTO | B28: rs8050136 | C28: CC | E28: 0 | F28: NEW
A29: GNPDA2 | B29: rs10938397 | C29: GG | E29: 1
A30: GNPDA2 | B30: rs10938397 | C30: GA | E30: 0
A31: GNPDA2 | B31: rs10938397 | C31: AA | E31: 0
A32: LEPR | B32: rs11208659 | C32: CC | E32: 1
A33: LEPR | B33: rs11208659 | C33: CT | E33: 0
A34: LEPR | B34: rs11208659 | C34: TT | E34: 0
A35: Leptin | B35: rs7799039 | C35: GA | E35: 0
A36: Leptin | B36: rs7799039 | C36: GG | E36: 0
A37: Leptin | B37: rs7799039 | C37: AA | E37: 1
A38: MC4R | B38: rs17782313 | C38: CC | E38: 2
A39: MC4R | B39: rs17782313 | C39: CT | E39: 1
A40: MC4R | B40: rs17782313 | C40: TT | E40: 0
...

Sheet RISCHIO T2D 3.0
A1: GENE | B1: SNP | C1: GEN | D1: CHECK | E1: PESO | F1: NOTE
A2: FABP2 | B2: rs1799883 | C2: TT | E2: 2
A3: FABP2 | B3: rs1799883 | C3: TC | E3: 0
A4: FABP2 | B4: rs1799883 | C4: CC | E4: 0
A5: TCFL2 | B5: rs7903146 | C5: TT | E5: 2
A6: TCFL2 | B6: rs7903146 | C6: CT | E6: 1
A7: TCFL2 | B7: rs7903146 | C7: CC | E7: 0
A8: GCK | B8: rs1799884 | C8: TT | E8: 2
A9: GCK | B9: rs1799884 | C9: TC | E9: 1
A10: GCK | B10: rs1799884 | C10: CC | E10: 0
A11: GCKR | B11: rs780094 | C11: TT | E11: 2
A12: GCKR | B12: rs780094 | C12: TC | E12: 0
A13: GCKR | B13: rs780094 | C13: CC | E13: 0
... A16: SLC30A8 | B16: rs13266634 | C16: TT | E16: 0
A17: MTNR1B | B17: rs10830963 | C17: GG | E17: 2 | F17: higher gestational diabetes risk
A18: MTNR1B | B18: rs10830963 | C18: GC | E18: 1 | F18: higher gestational diabetes risk
A19: MTNR1B | B19: rs10830963 | C19: CC | E19: 0 | F19: higher gestational diabetes risk
A20: FTO | B20: rs9939609 | C20: AA | E20: 5
A21: FTO | B21: rs9939609 | C21: AT | E21: 3
A22: FTO | B22: rs9939609 | C22: TT | E22: 0
A23: PPARG | B23: rs1801282 | C23: GG | E23: 2
A24: PPARG | B24: rs1801282 | C24: GC | E24: 1
A25: PPARG | B25: rs1801282 | C25: CC | E25: 0
A26: FTO | B26: rs1421085 | C26: CC | E26: 5
A27: FTO | B27: rs1421085 | C27: CT | E27: 3
A28: FTO | B28: rs1421085 | C28: TT | E28: 0
A29: ADIPOq | B29: rs17300539 | C29: CC | E29: 1 | F29: A allele confered protection from weight regain
A30: ADIPOq | B30: rs17300539 | C30: CT | E30: 0
A31: ADIPOq | B31: rs17300539 | C31: TT | E31: -1
A32: FTO | B32: rs8050136 | C32: AA | E32: 5 | F32: NEW
A33: FTO | B33: rs8050136 | C33: AC | E33: 3 | F33: NEW
A34: FTO | B34: rs8050136 | C34: CC | E34: 0 | F34: NEW
A35: SLC2A2 | B35: rs5400 | C35: TT | E35: 2 | F35: higher sugar consumption
A36: SLC2A3 | B36: rs5401 | C36: CT | E36: 1 | F36: higher sugar consumption
A37: SLC2A4 | B37: rs5402 | C37: CC | E37: 0 | F37: higher sugar consumption
B38: ALTO | C38: >20
B39: MEDIO | C39: 15-19
B40: LIEVE | C40: 7-14
B41: NON EVIDENTE | C41: 0-6

Sheet RISCHIO CARDIO 3.0
A1: GENE | B1: SNP | C1: GEN | D1: CHECK | E1: PESO | F1: NOTE
A2: APOE | B2: rs429358/rs7412 | C2: TT/TT | E2: 2 | F2: LDL tendenzialmente ridotto; possibile aumento dei trigliceridi
A3: APOE | B3: rs429358/rs7412 | C3: TC/TT | E3: 0
A4: APOE | B4: rs429358/rs7412 | C4: CC/TT | E4: 0
A5: APOE | B5: rs429358/rs7412 | C5: TT/TC | E5: 0
A6: APOE | B6: rs429358/rs7412 | C6: TC/TC | E6: 4 | F6: Aumento del colesterolo LDL
A7: APOE | B7: rs429358/rs7412 | C7: CC/TC | E7: 0
A8: APOE | B8: rs429358/rs7412 | C8: TT/CC | E8: 0
A9: APOE | B9: rs429358/rs7412 | C9: TC/CC | E9: 4 | F9: Aumento marcato del colesterolo LDL
A10: APOE | B10: rs429358/rs7412 | C10: CC/CC | E10: 7 | F10: Profilo lipidico fortemente aterogeno (LDL elevato)
A11: MTHFR | B11: rs1801133/rs1801131 | C11: GG/TT | D11: 1 | E11: 0
A12: MTHFR | B12: rs1801133/rs1801131 | C12: GG/TG | D12: 0.83 | E12: 0
A13: MTHFR | B13: rs1801133/rs1801131 | C13: GG/GG | D13: 0.61 | E13: 0
A14: MTHFR | B14: rs1801133/rs1801131 | C14: GA/TT | D14: 0.66 | E14: 1 | F14: CONTROLLO DEI LIVELLI DI OMOCISTEINA | G14: dipende dai folati se bassi si rischio CAD
A15: MTHFR | B15: rs1801133/rs1801131 | C15: GA/TG | D15: 0.48 | E15: 2 | F15: CONTROLLO DEI LIVELLI DI OMOCISTEINA | G15: dipende dai folati se bassi si rischio CAD
A16: MTHFR | B16: rs1801133/rs1801131 | C16: GA/GG | D16: nd | E16: 2 | F16: CONTROLLO DEI LIVELLI DI OMOCISTEINA | G16: dipende dai folati se bassi si rischio CAD
A17: MTHFR | B17: rs1801133/rs1801131 | C17: AA/TT | D17: 0.25 | E17: 3 | F17: CONTROLLO DEI LIVELLI DI OMOCISTEINA | G17: dipende dai folati se bassi si rischio CAD
A18: MTHFR | B18: rs1801133/rs1801131 | C18: AA/TG | D18: nd | E18: 2 | F18: CONTROLLO DEI LIVELLI DI OMOCISTEINA | G18: dipende dai folati se bassi si rischio CAD
A19: MTHFR | B19: rs1801133/rs1801131 | C19: AA/GG | D19: nd | E19: 2 | F19: CONTROLLO DEI LIVELLI DI OMOCISTEINA | G19: dipende dai folati se bassi si rischio CAD
A20: FABP2 | B20: rs1799883 | C20: TT | E20: 1
A21: FABP2 | B21: rs1799883 | C21: TC | E21: 0
A22: FABP2 | B22: rs1799883 | C22: CC | E22: 0
A23: ADIPOq | B23: rs17300539 | C23: CC | E23: 1
A24: ADIPOq | B24: rs17300539 | C24: CT | E24: 0
A25: ADIPOq | B25: rs17300539 | C25: TT | E25: 0
A26: FTO | B26: rs9939609 | C26: AA | E26: 2
A27: FTO | B27: rs9939609 | C27: AT | E27: 1
A28: FTO | B28: rs9939609 | C28: TT | E28: 0
A29: PPARG | B29: rs1801282 | C29: GG | E29: 2
A30: PPARG | B30: rs1801282 | C30: GC | E30: 1
A31: PPARG | B31: rs1801282 | C31: CC | E31: 0
... A34: TCFL2 | B34: rs7903146 | C34: CC | E34: 0
A35: FADS2 | B35: rs174601 | C35: TT | E35: 1 | F35: risk of coronary artery disease and ischemic stroke
A36: FADS2 | B36: rs174601 | C36: TC | E36: 0
A37: FADS2 | B37: rs174601 | C37: CC | E37: 0
A38: FADS1 | B38: rs174546 | C38: TT | E38: 1 | F38: risk of coronary artery disease and ischemic stroke
A39: FADS1 | B39: rs174546 | C39: TC | E39: 0
A40: FADS1 | B40: rs174546 | C40: CC | E40: 0
A41: APOA5 | B41: rs662799 | C41: GG | E41: 2 | F41: higher early heart attack risk; less weight gain on high fat diets
A42: APOA5 | B42: rs662799 | C42: GA | E42: 1 | F42: higher early heart attack risk; less weight gain on high fat diets
...

Sheet RIS PLUS3.0
A1: GENE | B1: SNP | C1: GEN | D1: PESO | E1: NOTE
A2: CYP1A2 | B2: rs762551 | C2: AA | D2: 1 | E2: Caffeina
A3: CYP1A2 | B3: rs762551 | C3: AC | D3: -1 | E3: Caffeina
A4: CYP1A2 | B4: rs762551 | C4: CC | D4: -1 | E4: Caffeina
A5: ALDOB | B5: rs76917243 | C5: TT | D5: 1 | E5: Fruttosio
A6: ALDOB | B6: rs76917243 | C6: TG | D6: 0 | E6: Fruttosio
A7: ALDOB | B7: rs76917243 | C7: GG | D7: 0 | E7: Fruttosio
A8: ALDOB | B8: rs1800546 | C8: GG | D8: 2 | E8: Fruttosio | F8: NEW
A9: ALDOB | B9: rs1800546 | C9: GC | D9: 1 | E9: Fruttosio | F9: NEW
A10: ALDOB | B10: rs1800546 | C10: CC | D10: 0 | E10: Fruttosio | F10: NEW
A11: LCT (MCM6) | B11: rs4988235 | C11: GG | D11: 1 | E11: Lattosio
A12: LCT (MCM6) | B12: rs4988235 | C12: GA | D12: 0 | E12: Lattosio
A13: LCT (MCM6) | B13: rs4988235 | C13: AA | D13: 0 | E13: Lattosio
A14: ALDH2 | B14: rs671 | C14: AA | D14: 1 | E14: Sens. Alcol
A15: ALDH2 | B15: rs671 | C15: AG | D15: 0 | E15: Sens. Alcol
A16: ALDH2 | B16: rs671 | C16: GG | D16: 0 | E16: Sens. Alcol
A17: NTN4 | B17: rs2367563 | C17: TT | D17: 1 | E17: INT NICHEL
A18: NTN5 | B18: rs2367564 | C18: TC | D18: 0 | E18: INT NICHEL
A19: NTN6 | B19: rs2367565 | C19: CC | D19: 0 | E19: INT NICHEL
A20: New Rules
A21: Sens. Alcol >=2
A22: Intolleranza al fruttosio >=3
A23: Intolleranza al lattosio >=1
A24: Sensibilità al nichel >=1
A25: metabolismo caffeina =1 veloce, 0 lento

Sheet RISCHIO VITA 3.0
A1: Assay ID | B1: GENE | C1: SNP | D1: GEN | E1: PESO | F1: NOTE
A2: C___1085600_10 | B2: HFE | C2: rs1799945/rs1800562 | D2: GG/AA | E2: 1 | F2: Emocromatosi
B3: HFE | C3: rs1799945/rs1800562 | D3: GG/AG | E3: 1 | F3: lieve alterazione dei livelli di ferro
B4: HFE | C4: rs1799945/rs1800562 | D4: GG/GG | E4: 1 | F4: lieve alterazione dei livelli di ferro
B5: HFE | C5: rs1799945/rs1800562 | D5: GC/AA | E5: 1 | F5: Emocromatosi
B6: HFE | C6: rs1799945/rs1800562 | D6: GC/AG | E6: 1 | F6: Emocromatosi
B7: HFE | C7: rs1799945/rs1800562 | D7: GC/GG | E7: 0 | F7: Emocromatosi
B8: HFE | C8: rs1799945/rs1800562 | D8: CC/AA | E8: 1 | F8: Emocromatosi
B9: HFE | C9: rs1799945/rs1800562 | D9: CC/AG | E9: 0 | F9: Emocromatosi
B10: HFE | C10: rs1799945/rs1800562 | D10: CC/GG | E10: 0 | F10: Emocromatosi
A11: C___3289902_10 | B11: TMPRSS6 | C11: rs855791 | D11: AA | E11: 1 | F11: Ferro Basso
B12: TMPRSS6 | C12: rs855791 | D12: AG | E12: 0 | F12: Ferro Basso
B13: TMPRSS6 | C13: rs855791 | D13: GG | E13: 0 | F13: Ferro Basso
A14: C__11885329_10 | B14: TMPRSS6 | C14: rs4820268 | D14: GG | E14: 0 | F14: Ferro Basso
B15: TMPRSS6 | C15: rs4820268 | D15: GA | E15: 0 | F15: Ferro Basso
B16: TMPRSS6 | C16: rs4820268 | D16: AA | E16: 1 | F16: Ferro Basso
B17: MTHFR | C17: rs1801133/rs1801131 | D17: GG/TT | E17: 0 | F17: Low Vitamin B9
B18: MTHFR | C18: rs1801133/rs1801131 | D18: GG/TG | E18: 0 | F18: Low Vitamin B9
B19: MTHFR | C19: rs1801133/rs1801131 | D19: GG/GG | E19: 0 | F19: Low Vitamin B9
B20: MTHFR | C20: rs1801133/rs1801131 | D20: GA/TT | E20: 1 | F20: Low Vitamin B9
B21: MTHFR | C21: rs1801133/rs1801131 | D21: GA/TG | E21: 2 | F21: Low Vitamin B9
B22: MTHFR | C22: rs1801133/rs1801131 | D22: GA/GG | E22: 2 | F22: Low Vitamin B9
B23: MTHFR | C23: rs1801133/rs1801131 | D23: AA/TT | E23: 3 | F23: Low Vitamin B9
B24: MTHFR | C24: rs1801133/rs1801131 | D24: AA/TG | E24: 2 | F24: Low Vitamin B9
B25: MTHFR | C25: rs1801133/rs1801131 | D25: AA/GG | E25: 2 | F25: Low Vitamin B9
B26: GC | C26: rs1155563 | D26: CC | E26: 1 | F26: Low Vitamin D
... B37: GC | C37: rs4588/rs7041 | D37: CC/CC | E37: 0 | F37: Low Vitamin D
A38: CYP2R1 | B38: CYP2R1 | C38: rs10741657 | D38: AA | E38: -1 | F38: Low Vitamin D
B39: CYP2R1 | C39: rs10741657 | D39: AG | E39: 0 | F39: Low Vitamin D
B40: CYP2R1 | C40: rs10741657 | D40: GG | E40: 1 | F40: Low Vitamin D
B41: FUT2 | C41: rs602662 | D41: GG | E41: 1 | F41: Low Vitamin B12
B42: FUT2 | C42: rs602662 | D42: GA | E42: 0 | F42: Low Vitamin B12
B43: FUT2 | C43: rs602662 | D43: AA | E43: -1 | F43: Low Vitamin B12
B44: MTHFD1 | C44: rs2236225 | D44: CC | E44: 0 | F44: Low Vitamin B9
B45: MTHFD1 | C45: rs2236225 | D45: CT | E45: 1 | F45: Low Vitamin B9
B46: MTHFD1 | C46: rs2236225 | D46: TT | E46: 2 | F46: Low Vitamin B9
B47: BCMO1 | C47: rs7501331 | D47: CC | E47: 0 | F47: Low Vitamin A
B48: BCMO1 | C48: rs7501331 | D48: CT | E48: 1 | F48: Low Vitamin A
B49: BCMO1 | C49: rs7501331 | D49: TT | E49: 1 | F49: Low Vitamin A
B50: BCMO1 | C50: rs12934922 | D50: AA | E50: 0 | F50: Low Vitamin A
...

Sheet RISCHIO SPORT
A1: GENE | B1: SNP | C1: GEN | D1: CHECK | E1: PESO | F1: NOTE
A2: COL1A1 | B2: rs1800012 | C2: AA | E2: 1 | F2: Osteoartrosi e fratture
A3: COL1A1 | B3: rs1800012 | C3: CC | E3: 0 | F3: Osteoartrosi e fratture
A4: COL1A1 | B4: rs1800012 | C4: AC | E4: 0 | F4: Osteoartrosi e fratture
A5: COL5A1 | B5: rs12722 | C5: TT | E5: 4 | F5: Crampi-Debolezza Tendinea
A6: COL5A1 | B6: rs12722 | C6: TC | E6: 2 | F6: Crampi-Debolezza Tendinea
A7: COL5A1 | B7: rs12722 | C7: CC | E7: 0 | F7: Crampi-Debolezza Tendinea
A8: COL27A1/TNC | B8: rs946053/rs13321/rs2104772 | C8: GG/CC/AA | E8: 3 | F8: Tendinopatie
A9: COL27A1/TNC | B9: rs946053/rs13321/rs2104772 | C9: GG/CC/AT | E9: 3 | F9: Tendinopatie
A10: COL27A1/TNC | B10: rs946053/rs13321/rs2104772 | C10: GG/CC/TT | E10: -1 | F10: Tendinopatie
A11: COL27A1/TNC | B11: rs946053/rs13321/rs2104772 | C11: GG/CG/AA | E11: 3 | F11: Tendinopatie
A12: COL27A1/TNC | B12: rs946053/rs13321/rs2104772 | C12: GG/CG/AT | E12: 3 | F12: Tendinopatie
A13: COL27A1/TNC | B13: rs946053/rs13321/rs2104772 | C13: GG/CG/TT | E13: 0 | F13: Tendinopatie
A14: COL27A1/TNC | B14: rs946053/rs13321/rs2104772 | C14: GG/GG/AA | E14: 0 | F14: Tendinopatie
A15: COL27A1/TNC | B15: rs946053/rs13321/rs2104772 | C15: GG/GG/AT | E15: 0 | F15: Tendinopatie
A16: COL27A1/TNC | B16: rs946053/rs13321/rs2104772 | C16: GG/GG/TT | E16: 0 | F16: Tendinopatie
A17: COL27A1/TNC | B17: rs946053/rs13321/rs2104772 | C17: GT/CC/AA | E17: 3 | F17: Tendinopatie
A18: COL27A1/TNC | B18: rs946053/rs13321/rs2104772 | C18: GT/CC/AT | E18: 3 | F18: Tendinopatie
A19: COL27A1/TNC | B19: rs946053/rs13321/rs2104772 | C19: GT/CC/TT | E19: -1 | F19: Tendinopatie
A20: COL27A1/TNC | B20: rs946053/rs13321/rs2104772 | C20: GT/CG/AA | E20: 0 | F20: Tendinopatie
A21: COL27A1/TNC | B21: rs946053/rs13321/rs2104772 | C21: GT/CG/AT | E21: 0 | F21: Tendinopatie
A22: COL27A1/TNC | B22: rs946053/rs13321/rs2104772 | C22: GT/CG/TT | E22: 0 | F22: Tendinopatie
A23: COL27A1/TNC | B23: rs946053/rs13321/rs2104772 | C23: GT/GG/AA | E23: 0 | F23: Tendinopatie
A24: COL27A1/TNC | B24: rs946053/rs13321/rs2104772 | C24: GT/GG/AT | E24: 0 | F24: Tendinopatie
A25: COL27A1/TNC | B25: rs946053/rs13321/rs2104772 | C25: GT/GG/TT | E25: 0 | F25: Tendinopatie
A26: COL27A1/TNC | B26: rs946053/rs13321/rs2104772 | C26: TT/CC/AA | E26: 0 | F26: Tendinopatie
A27: COL27A1/TNC | B27: rs946053/rs13321/rs2104772 | C27: TT/CC/AT | E27: 0 | F27: Tendinopatie
A28: COL27A1/TNC | B28: rs946053/rs13321/rs2104772 | C28: TT/CC/TT | E28: 0 | F28: Tendinopatie
... A34: COL27A1/TNC | B34: rs946053/rs13321/rs2104772 | C34: TT/GG/TT | E34: 0 | F34: Tendinopatie
A35: TNC | B35: rs1330363 | C35: CC | E35: 2 | F35: Tendinopatie
A36: TNC | B36: rs1330363 | C36: TC | E36: 1 | F36: Tendinopatie
A37: TNC | B37: rs1330363 | C37: TT | E37: 0 | F37: Tendinopatie
A38: MMP3 | B38: rs591058 | C38: TT | E38: 0 | F38: Tendinopatie
A39: MMP3 | B39: rs591058 | C39: CC | E39: 2 | F39: Tendinopatie
A40: MMP3 | B40: rs591058 | C40: CT | E40: 1 | F40: Tendinopatie
A41: MMP3 | B41: rs679620 | C41: TT | E41: 0 | F41: Tendinopatie
A42: MMP3 | B42: rs679620 | C42: CC | E42: 2 | F42: Tendinopatie
A43: MMP3 | B43: rs679620 | C43: TC | E43: 1 | F43: Tendinopatie
A44: COL12A1 | B44: rs970547 | C44: TT | E44: 2 | F44: Tendinopatie
A45: COL12A1 | B45: rs970547 | C45: TC | E45: 1 | F45: Tendinopatie
...

Sheet RISCHIO AGING 
A1: GENE | B1: SNP | C1: GEN | D1: CHECK | E1: PESO | F1: NOTE
A2: CRP | B2: rs1205 | C2: CC | E2: 1 | F2: Rischio Cardio
A3: CRP | B3: rs1205 | C3: CT | E3: 0 | F3: Rischio Cardio
A4: CRP | B4: rs1205 | C4: TT | E4: 0 | F4: Rischio Cardio
A5: SOD3 | B5: rs2536512 | C5: AA | E5: 1 | F5: Calo att. antiossidante
A6: SOD3 | B6: rs2536512 | C6: AG | E6: 0 | F6: Calo att. antiossidante
A7: SOD3 | B7: rs2536512 | C7: GG | E7: 0 | F7: Calo att. antiossidante
A8: IL1B | B8: rs16944 | C8: AA | E8: 0 | F8: Funzioni cognitive
A9: IL1B | B9: rs16944 | C9: AG | E9: 0 | F9: Funzioni cognitive
A10: IL1B | B10: rs16944 | C10: GG | E10: 1 | F10: Funzioni cognitive
A11: NQO1 | B11: rs1800566 | C11: AA | E11: 1 | F11: Calo att. antiossidante
A12: NQO1 | B12: rs1800566 | C12: AG | E12: 0 | F12: Calo att. antiossidante
A13: NQO1 | B13: rs1800566 | C13: GG | E13: 0 | F13: Calo att. antiossidante
... A49: SOD3 | B49: rs699473 | C49: TT | E49: 0 | F49: Rischio Cardio+Calo att. antiossidante
A51: rischio malattie cardiovascoalri =ATTENZIONE QUESTI GENI SONO DA CONSIDERARE INSIEME AGLI ALTRI DELLE PATOLOGIE CARDIOVASCOLARI
A52: rischio di sviluppare forme lievi di diabete e ipercolesterolemia=ATTENZIONE QUESTI GENI SONO DA CONSIDERARE INSIEME AGLI ALTRI DEL DIABETE
A53: calo attività antiossidante>=2
A54: ridotte funzioni cognitive>=2
A55: Elast. Pelle>=1
A56: Idrat. Pelle>=1

Sheet RISCHIO MAMMA
A1: GENE | B1: SNP | C1: GEN | D1: CHECK | E1: PESO | F1: NOTE
A2: AGT | B2: rs11568020 | C2: TT | E2: 1 | F2: Sodium
A3: AGT | B3: rs11568020 | C3: TC | E3: 0 | F3: Sodium
A4: AGT | B4: rs11568020 | C4: CC | E4: 0 | F4: Sodium
A5: AGT | B5: rs5050 | C5: GG | E5: 1 | F5: Sodium
A6: AGT | B6: rs5050 | C6: GT | E6: 0 | F6: Sodium
A7: AGT | B7: rs5050 | C7: TT | E7: 0 | F7: Sodium
A8: CLCNKA | B8: rs848307 1a | C8: GG | E8: 1 | F8: Sodium
A9: CLCNKA | B9: rs848307 1a | C9: GA | E9: 0 | F9: Sodium
A10: CLCNKA | B10: rs848307 1a | C10: AA | E10: 0 | F10: Sodium
A11: CLCNKA | B11: rs1739843 3a | C11: CC | E11: 1 | F11: Sodium
A12: CLCNKA | B12: rs1739843 3a | C12: CT | E12: 0 | F12: Sodium
A13: CLCNKA | B13: rs1739843 3a | C13: TT | E13: 0 | F13: Sodium
... A55: WNK1 | B55: rs880054 | C55: GG | E55: 1 | F55: Potassio basso
A59: Sodium>6 | B59: PREDISPOSIZIONE GENETICA AD ELEVATI LIVELLI DI SODIO E CONSEGUENTE IPERTENSIONE
A60: Zinc>2 | B60: PREDISPOSIZIONE GENETICA A RIDOTTI LIVELLI DI ZINCO
A61: LOW VITAMIN B9 >=4 | B61: CONTROLLARE ACIDO FOLICO
A62: Vitamin D >= 3 | B62: CONTROLLARE VIT D
A63: Vitamin B6 >= 2
A64: Vitamin B12 & LOW VITAMIN B9 >=4 | B64: CONTROLLARE VIT B12
A65: Potassio >=1 | B65: CONTROLLARE LIVELLI DI POTASSIO
